Workbook
Name alex: #REF!
Name APURAÇÃO01: #REF!
Name denner: #REF!
Name joao: #REF!
Name lucci: #REF!
Name lucci_pai: #REF!
Name luiza: #REF!
Name manocchio: #REF!
Name marcao: #REF!
Name rampazzo: #REF!
Name stabelinni: #REF!

Sheet Resultados
A1: COPA 2026 - TABELA DE APOSTAS | F1: Pagamento = Pix | J1: 50
A2: Nome:
A3: Celular: | D3: e-mail:
A4: JOGOS | B4: GRUPO | H4: DIA | J4: HORA
A5: 1 | B5: A | C5: México | E5: X | G5: África do Sul | H5: 46184 | I5: =H5 | J5: 0.66666667
A6: 2 | B6: A | C6: Coreia do Sul | E6: X | G6: Tchéquia | H6: 46184 | I6: =H6 | J6: 0.95833333
A7: 3 | B7: B | C7: Canadá | E7: X | G7: Bósnia | H7: 46185 | I7: =H7 | J7: 0.66666667
A8: 4 | B8: D | C8: EUA | E8: X | G8: Paraguai | H8: 46185 | I8: =H8 | J8: 0.91666667
A9: 5 | B9: D | C9: Austrália | D9: 2 | E9: X | F9: 0 | G9: Turquia | H9: 46186 | I9: =H9 | J9: 0.041666667
A10: 6 | B10: B | C10: Catar | D10: 1 | E10: X | F10: 1 | G10: Suíça | H10: 46186 | I10: =H10 | J10: 0.66666667
A11: 7 | B11: C | C11: Brasil | D11: 1 | E11: X | F11: 1 | G11: Marrocos | H11: 46186 | I11: =H11 | J11: 0.79166667
A12: 8 | B12: C | C12: Haiti | D12: 0 | E12: X | F12: 1 | G12: Escócia | H12: 46186 | I12: =H12 | J12: 0.91666667
A13: 9 | B13: E | C13: Alemanha | D13: 7 | E13: X | F13: 1 | G13: Curaçau | H13: 46187 | I13: =H13 | J13: 0.58333333
A14: 10 | B14: F | C14: Holanda | D14: 2 | E14: X | F14: 2 | G14: Japão | H14: 46187 | I14: =H14 | J14: 0.70833333
A15: 11 | B15: E | C15: Costa do Marfim | D15: 1 | E15: X | F15: 0 | G15: Equador | H15: 46187 | I15: =H15 | J15: 0.83333333
A16: 12 | B16: F | C16: Suécia | D16: 5 | E16: X | F16: 1 | G16: Tunísia | H16: 46187 | I16: =H16 | J16: 0.95833333
A17: 13 | B17: H | C17: Espanha | D17: 0 | E17: X | F17: 0 | G17: Cabo Verde | H17: 46188 | I17: =H17 | J17: 0.54166667
A18: 14 | B18: G | C18: Bélgica | D18: 1 | E18: X | F18: 1 | G18: Egito | H18: 46188 | I18: =H18 | J18: 0.66666667
A19: 15 | B19: H | C19: Arábia Saudita | D19: 1 | E19: X | F19: 1 | G19: Uruguai | H19: 46188 | I19: =H19 | J19: 0.79166667
A20: 16 | B20: G | C20: Irã | D20: 2 | E20: X | F20: 2 | G20: Nova Zelândia | H20: 46188 | I20: =H20 | J20: 0.91666667
... A76: 72 | B76: K | C76: Colômbia | D76: 0 | E76: X | F76: 0 | G76: Portugal | H76: 46200 | I76: =H76 | J76: 0.91666667
A77: 73 | B77: R32 | C77: África do Sul | D77: 0 | E77: X | F77: 1 | G77: Canadá | H77: 2026-06-28 | I77: =H77 | J77: 16:00
A78: 74 | B78: R32 | C78: Alemanha | D78: 1 | E78: X | F78: 1 | G78: Paraguai | H78: 2026-06-29 | I78: =H78 | J78: 17:30
A79: 75 | B79: R32 | C79: Holanda | D79: 1 | E79: X | F79: 1 | G79: Marrocos | H79: 2026-06-29 | I79: =H79 | J79: 22:00
A80: 76 | B80: R32 | C80: Brasil | D80: 2 | E80: X | F80: 1 | G80: Japão | H80: 2026-06-29 | I80: =H80 | J80: 14:00
A81: 77 | B81: R32 | C81: França | D81: 3 | E81: X | F81: 0 | G81: Suécia | H81: 2026-06-30 | I81: =H81 | J81: 18:00
A82: 78 | B82: R32 | C82: Costa do Marfim | D82: 1 | E82: X | F82: 2 | G82: Noruega | H82: 2026-06-30 | I82: =H82 | J82: 14:00
A83: 79 | B83: R32 | C83: México | D83: 2 | E83: X | F83: 0 | G83: Equador | H83: 2026-06-30 | I83: =H83 | J83: 22:00
A84: 80 | B84: R32 | C84: Inglaterra | D84: 2 | E84: X | F84: 1 | G84: RD Congo | H84: 2026-07-01 | I84: =H84 | J84: 13:00
A85: 81 | B85: R32 | C85: EUA | D85: 2 | E85: X | F85: 0 | G85: Bósnia | H85: 2026-07-01 | I85: =H85 | J85: 21:00
A86: 82 | B86: R32 | C86: Bélgica | D86: 3 | E86: X | F86: 2 | G86: Senegal | H86: 2026-07-01 | I86: =H86 | J86: 17:00
A87: 83 | B87: R32 | C87: Portugal | D87: 2 | E87: X | F87: 1 | G87: Croácia | H87: 2026-07-02 | I87: =H87 | J87: 20:00
A88: 84 | B88: R32 | C88: Espanha | D88: 3 | E88: X | F88: 0 | G88: Áustria | H88: 2026-07-02 | I88: =H88 | J88: 16:00
... A108: 104 | B108: Final | C108: Espanha | D108: 1 | E108: X | F108: 0 | G108: Argentina | H108: 2026-07-19 | I108: =H108 | J108: 16:00

Sheet Beda
A1: COPA 2026 - TABELA DE APOSTAS | F1: Pagamento = Pix | J1: 50
A2: Nome:
A3: Celular: | D3: e-mail:
A4: JOGOS | B4: GRUPO | H4: DIA | J4: HORA
A5: 1 | B5: A | C5: México | E5: X | G5: África do Sul | H5: 46184 | I5: 46184 | J5: 0.66666667 | K5: =IF(AND(ISNUMBER(D5),ISNUMBER(F5),ISNUMBER(Resultados!D5),ISNUMBER(Resultados!F5)),IF(SIGN(D5-F5)=SIGN(Resultados!D5-Resultados!F5),2,0)+IF(D5=Resultados!D5,1,0)+IF(F5=Resultados!F5,1,0)+IF(D5+F5=Resultados!D5+Resultados!F5,1,0),0)
A6: 2 | B6: A | C6: Coreia do Sul | E6: X | G6: Tchéquia | H6: 46184 | I6: 46184 | J6: 0.95833333 | K6: =IF(AND(ISNUMBER(D6),ISNUMBER(F6),ISNUMBER(Resultados!D6),ISNUMBER(Resultados!F6)),IF(SIGN(D6-F6)=SIGN(Resultados!D6-Resultados!F6),2,0)+IF(D6=Resultados!D6,1,0)+IF(F6=Resultados!F6,1,0)+IF(D6+F6=Resultados!D6+Resultados!F6,1,0),0)
A7: 3 | B7: B | C7: Canadá | E7: X | G7: Bósnia | H7: 46185 | I7: 46185 | J7: 0.66666667 | K7: =IF(AND(ISNUMBER(D7),ISNUMBER(F7),ISNUMBER(Resultados!D7),ISNUMBER(Resultados!F7)),IF(SIGN(D7-F7)=SIGN(Resultados!D7-Resultados!F7),2,0)+IF(D7=Resultados!D7,1,0)+IF(F7=Resultados!F7,1,0)+IF(D7+F7=Resultados!D7+Resultados!F7,1,0),0)
A8: 4 | B8: D | C8: EUA | E8: X | G8: Paraguai | H8: 46185 | I8: 46185 | J8: 0.91666667 | K8: =IF(AND(ISNUMBER(D8),ISNUMBER(F8),ISNUMBER(Resultados!D8),ISNUMBER(Resultados!F8)),IF(SIGN(D8-F8)=SIGN(Resultados!D8-Resultados!F8),2,0)+IF(D8=Resultados!D8,1,0)+IF(F8=Resultados!F8,1,0)+IF(D8+F8=Resultados!D8+Resultados!F8,1,0),0)
A9: 5 | B9: D | C9: Austrália | E9: X | G9: Turquia | H9: 46186 | I9: 46186 | J9: 0.041666667 | K9: =IF(AND(ISNUMBER(D9),ISNUMBER(F9),ISNUMBER(Resultados!D9),ISNUMBER(Resultados!F9)),IF(SIGN(D9-F9)=SIGN(Resultados!D9-Resultados!F9),2,0)+IF(D9=Resultados!D9,1,0)+IF(F9=Resultados!F9,1,0)+IF(D9+F9=Resultados!D9+Resultados!F9,1,0),0)
A10: 6 | B10: B | C10: Catar | D10: 0 | E10: X | F10: 2 | G10: Suíça | H10: 46186 | I10: 46186 | J10: 0.66666667 | K10: =IF(AND(ISNUMBER(D10),ISNUMBER(F10),ISNUMBER(Resultados!D10),ISNUMBER(Resultados!F10)),IF(SIGN(D10-F10)=SIGN(Resultados!D10-Resultados!F10),2,0)+IF(D10=Resultados!D10,1,0)+IF(F10=Resultados!F10,1,0)+IF(D10+F10=Resultados!D10+Resultados!F10,1,0),0)
A11: 7 | B11: C | C11: Brasil | D11: 2 | E11: X | F11: 1 | G11: Marrocos | H11: 46186 | I11: 46186 | J11: 0.79166667 | K11: =IF(AND(ISNUMBER(D11),ISNUMBER(F11),ISNUMBER(Resultados!D11),ISNUMBER(Resultados!F11)),IF(SIGN(D11-F11)=SIGN(Resultados!D11-Resultados!F11),2,0)+IF(D11=Resultados!D11,1,0)+IF(F11=Resultados!F11,1,0)+IF(D11+F11=Resultados!D11+Resultados!F11,1,0),0)
A12: 8 | B12: C | C12: Haiti | D12: 1 | E12: X | F12: 1 | G12: Escócia | H12: 46186 | I12: 46186 | J12: 0.91666667 | K12: =IF(AND(ISNUMBER(D12),ISNUMBER(F12),ISNUMBER(Resultados!D12),ISNUMBER(Resultados!F12)),IF(SIGN(D12-F12)=SIGN(Resultados!D12-Resultados!F12),2,0)+IF(D12=Resultados!D12,1,0)+IF(F12=Resultados!F12,1,0)+IF(D12+F12=Resultados!D12+Resultados!F12,1,0),0)
A13: 9 | B13: E | C13: Alemanha | D13: 4 | E13: X | F13: 0 | G13: Curaçau | H13: 46187 | I13: 46187 | J13: 0.58333333 | K13: =IF(AND(ISNUMBER(D13),ISNUMBER(F13),ISNUMBER(Resultados!D13),ISNUMBER(Resultados!F13)),IF(SIGN(D13-F13)=SIGN(Resultados!D13-Resultados!F13),2,0)+IF(D13=Resultados!D13,1,0)+IF(F13=Resultados!F13,1,0)+IF(D13+F13=Resultados!D13+Resultados!F13,1,0),0)
A14: 10 | B14: F | C14: Holanda | D14: 2 | E14: X | F14: 1 | G14: Japão | H14: 46187 | I14: 46187 | J14: 0.70833333 | K14: =IF(AND(ISNUMBER(D14),ISNUMBER(F14),ISNUMBER(Resultados!D14),ISNUMBER(Resultados!F14)),IF(SIGN(D14-F14)=SIGN(Resultados!D14-Resultados!F14),2,0)+IF(D14=Resultados!D14,1,0)+IF(F14=Resultados!F14,1,0)+IF(D14+F14=Resultados!D14+Resultados!F14,1,0),0)
A15: 11 | B15: E | C15: Costa do Marfim | D15: 1 | E15: X | F15: 1 | G15: Equador | H15: 46187 | I15: 46187 | J15: 0.83333333 | K15: =IF(AND(ISNUMBER(D15),ISNUMBER(F15),ISNUMBER(Resultados!D15),ISNUMBER(Resultados!F15)),IF(SIGN(D15-F15)=SIGN(Resultados!D15-Resultados!F15),2,0)+IF(D15=Resultados!D15,1,0)+IF(F15=Resultados!F15,1,0)+IF(D15+F15=Resultados!D15+Resultados!F15,1,0),0)
A16: 12 | B16: F | C16: Suécia | D16: 2 | E16: X | F16: 0 | G16: Tunísia | H16: 46187 | I16: 46187 | J16: 0.95833333 | K16: =IF(AND(ISNUMBER(D16),ISNUMBER(F16),ISNUMBER(Resultados!D16),ISNUMBER(Resultados!F16)),IF(SIGN(D16-F16)=SIGN(Resultados!D16-Resultados!F16),2,0)+IF(D16=Resultados!D16,1,0)+IF(F16=Resultados!F16,1,0)+IF(D16+F16=Resultados!D16+Resultados!F16,1,0),0)
A17: 13 | B17: H | C17: Espanha | D17: 3 | E17: X | F17: 0 | G17: Cabo Verde | H17: 46188 | I17: 46188 | J17: 0.54166667 | K17: =IF(AND(ISNUMBER(D17),ISNUMBER(F17),ISNUMBER(Resultados!D17),ISNUMBER(Resultados!F17)),IF(SIGN(D17-F17)=SIGN(Resultados!D17-Resultados!F17),2,0)+IF(D17=Resultados!D17,1,0)+IF(F17=Resultados!F17,1,0)+IF(D17+F17=Resultados!D17+Resultados!F17,1,0),0)
A18: 14 | B18: G | C18: Bélgica | D18: 2 | E18: X | F18: 0 | G18: Egito | H18: 46188 | I18: 46188 | J18: 0.66666667 | K18: =IF(AND(ISNUMBER(D18),ISNUMBER(F18),ISNUMBER(Resultados!D18),ISNUMBER(Resultados!F18)),IF(SIGN(D18-F18)=SIGN(Resultados!D18-Resultados!F18),2,0)+IF(D18=Resultados!D18,1,0)+IF(F18=Resultados!F18,1,0)+IF(D18+F18=Resultados!D18+Resultados!F18,1,0),0)
A19: 15 | B19: H | C19: Arábia Saudita | D19: 0 | E19: X | F19: 2 | G19: Uruguai | H19: 46188 | I19: 46188 | J19: 0.79166667 | K19: =IF(AND(ISNUMBER(D19),ISNUMBER(F19),ISNUMBER(Resultados!D19),ISNUMBER(Resultados!F19)),IF(SIGN(D19-F19)=SIGN(Resultados!D19-Resultados!F19),2,0)+IF(D19=Resultados!D19,1,0)+IF(F19=Resultados!F19,1,0)+IF(D19+F19=Resultados!D19+Resultados!F19,1,0),0)
A20: 16 | B20: G | C20: Irã | D20: 1 | E20: X | F20: 0 | G20: Nova Zelândia | H20: 46188 | I20: 46188 | J20: 0.91666667 | K20: =IF(AND(ISNUMBER(D20),ISNUMBER(F20),ISNUMBER(Resultados!D20),ISNUMBER(Resultados!F20)),IF(SIGN(D20-F20)=SIGN(Resultados!D20-Resultados!F20),2,0)+IF(D20=Resultados!D20,1,0)+IF(F20=Resultados!F20,1,0)+IF(D20+F20=Resultados!D20+Resultados!F20,1,0),0)
A21: 17 | B21: I | C21: França | D21: 2 | E21: X | F21: 1 | G21: Senegal | H21: 46189 | I21: 46189 | J21: 0.66666667 | K21: =IF(AND(ISNUMBER(D21),ISNUMBER(F21),ISNUMBER(Resultados!D21),ISNUMBER(Resultados!F21)),IF(SIGN(D21-F21)=SIGN(Resultados!D21-Resultados!F21),2,0)+IF(D21=Resultados!D21,1,0)+IF(F21=Resultados!F21,1,0)+IF(D21+F21=Resultados!D21+Resultados!F21,1,0),0)
... A76: 72 | B76: K | C76: Colômbia | D76: 1 | E76: X | F76: 1 | G76: Portugal | H76: 46200 | I76: 46200 | J76: 0.91666667 | K76: =IF(AND(ISNUMBER(D76),ISNUMBER(F76),ISNUMBER(Resultados!D76),ISNUMBER(Resultados!F76)),IF(SIGN(D76-F76)=SIGN(Resultados!D76-Resultados!F76),2,0)+IF(D76=Resultados!D76,1,0)+IF(F76=Resultados!F76,1,0)+IF(D76+F76=Resultados!D76+Resultados!F76,1,0),0)
A77: 73 | B77: R32 | C77: África do Sul | D77: 1 | E77: X | F77: 3 | G77: Canadá | H77: 2026-06-28 | I77: =H77 | J77: 16:00 | K77: =IF(AND(ISNUMBER(D77),ISNUMBER(F77),ISNUMBER(Resultados!D77),ISNUMBER(Resultados!F77)),IF(SIGN(D77-F77)=SIGN(Resultados!D77-Resultados!F77),2,0)+IF(D77=Resultados!D77,1,0)+IF(F77=Resultados!F77,1,0)+IF(D77+F77=Resultados!D77+Resultados!F77,1,0),0)
A78: 74 | B78: R32 | C78: Alemanha | D78: 2 | E78: X | F78: 1 | G78: Paraguai | H78: 2026-06-29 | I78: =H78 | J78: 17:30 | K78: 1
A79: 75 | B79: R32 | C79: Holanda | D79: 2 | E79: X | F79: 1 | G79: Marrocos | H79: 2026-06-29 | I79: =H79 | J79: 22:00 | K79: 1
A80: 76 | B80: R32 | C80: Brasil | D80: 2 | E80: X | F80: 1 | G80: Japão | H80: 2026-06-29 | I80: =H80 | J80: 14:00 | K80: =IF(AND(ISNUMBER(D80),ISNUMBER(F80),ISNUMBER(Resultados!D80),ISNUMBER(Resultados!F80)),IF(SIGN(D80-F80)=SIGN(Resultados!D80-Resultados!F80),2,0)+IF(D80=Resultados!D80,1,0)+IF(F80=Resultados!F80,1,0)+IF(D80+F80=Resultados!D80+Resultados!F80,1,0),0)
A81: 77 | B81: R32 | C81: França | D81: 3 | E81: X | F81: 1 | G81: Suécia | H81: 2026-06-30 | I81: =H81 | J81: 18:00 | K81: =IF(AND(ISNUMBER(D81),ISNUMBER(F81),ISNUMBER(Resultados!D81),ISNUMBER(Resultados!F81)),IF(SIGN(D81-F81)=SIGN(Resultados!D81-Resultados!F81),2,0)+IF(D81=Resultados!D81,1,0)+IF(F81=Resultados!F81,1,0)+IF(D81+F81=Resultados!D81+Resultados!F81,1,0),0)
A82: 78 | B82: R32 | C82: Costa do Marfim | D82: 1 | E82: X | F82: 2 | G82: Noruega | H82: 2026-06-30 | I82: =H82 | J82: 14:00 | K82: =IF(AND(ISNUMBER(D82),ISNUMBER(F82),ISNUMBER(Resultados!D82),ISNUMBER(Resultados!F82)),IF(SIGN(D82-F82)=SIGN(Resultados!D82-Resultados!F82),2,0)+IF(D82=Resultados!D82,1,0)+IF(F82=Resultados!F82,1,0)+IF(D82+F82=Resultados!D82+Resultados!F82,1,0),0)
A83: 79 | B83: R32 | C83: México | D83: 0 | E83: X | F83: 1 | G83: Equador | H83: 2026-06-30 | I83: =H83 | J83: 22:00 | K83: =IF(AND(ISNUMBER(D83),ISNUMBER(F83),ISNUMBER(Resultados!D83),ISNUMBER(Resultados!F83)),IF(SIGN(D83-F83)=SIGN(Resultados!D83-Resultados!F83),2,0)+IF(D83=Resultados!D83,1,0)+IF(F83=Resultados!F83,1,0)+IF(D83+F83=Resultados!D83+Resultados!F83,1,0),0)
A84: 80 | B84: R32 | C84: Inglaterra | D84: 3 | E84: X | F84: 0 | G84: RD Congo | H84: 2026-07-01 | I84: =H84 | J84: 13:00 | K84: =IF(AND(ISNUMBER(D84),ISNUMBER(F84),ISNUMBER(Resultados!D84),ISNUMBER(Resultados!F84)),IF(SIGN(D84-F84)=SIGN(Resultados!D84-Resultados!F84),2,0)+IF(D84=Resultados!D84,1,0)+IF(F84=Resultados!F84,1,0)+IF(D84+F84=Resultados!D84+Resultados!F84,1,0),0)
A85: 81 | B85: R32 | C85: EUA | D85: 2 | E85: X | F85: 0 | G85: Bósnia | H85: 2026-07-01 | I85: =H85 | J85: 21:00 | K85: =IF(AND(ISNUMBER(D85),ISNUMBER(F85),ISNUMBER(Resultados!D85),ISNUMBER(Resultados!F85)),IF(SIGN(D85-F85)=SIGN(Resultados!D85-Resultados!F85),2,0)+IF(D85=Resultados!D85,1,0)+IF(F85=Resultados!F85,1,0)+IF(D85+F85=Resultados!D85+Resultados!F85,1,0),0)
A86: 82 | B86: R32 | C86: Bélgica | D86: 1 | E86: X | F86: 2 | G86: Senegal | H86: 2026-07-01 | I86: =H86 | J86: 17:00 | K86: =IF(AND(ISNUMBER(D86),ISNUMBER(F86),ISNUMBER(Resultados!D86),ISNUMBER(Resultados!F86)),IF(SIGN(D86-F86)=SIGN(Resultados!D86-Resultados!F86),2,0)+IF(D86=Resultados!D86,1,0)+IF(F86=Resultados!F86,1,0)+IF(D86+F86=Resultados!D86+Resultados!F86,1,0),0)
A87: 83 | B87: R32 | C87: Portugal | D87: 1 | E87: X | F87: 0 | G87: Croácia | H87: 2026-07-02 | I87: =H87 | J87: 20:00 | K87: =IF(AND(ISNUMBER(D87),ISNUMBER(F87),ISNUMBER(Resultados!D87),ISNUMBER(Resultados!F87)),IF(SIGN(D87-F87)=SIGN(Resultados!D87-Resultados!F87),2,0)+IF(D87=Resultados!D87,1,0)+IF(F87=Resultados!F87,1,0)+IF(D87+F87=Resultados!D87+Resultados!F87,1,0),0)
A88: 84 | B88: R32 | C88: Espanha | D88: 2 | E88: X | F88: 1 | G88: Áustria | H88: 2026-07-02 | I88: =H88 | J88: 16:00 | K88: =IF(AND(ISNUMBER(D88),ISNUMBER(F88),ISNUMBER(Resultados!D88),ISNUMBER(Resultados!F88)),IF(SIGN(D88-F88)=SIGN(Resultados!D88-Resultados!F88),2,0)+IF(D88=Resultados!D88,1,0)+IF(F88=Resultados!F88,1,0)+IF(D88+F88=Resultados!D88+Resultados!F88,1,0),0)
A89: 85 | B89: R32 | C89: Suíça | D89: 2 | E89: X | F89: 0 | G89: Argélia | H89: 2026-07-03 | I89: =H89 | J89: 00:00 | K89: =IF(AND(ISNUMBER(D89),ISNUMBER(F89),ISNUMBER(Resultados!D89),ISNUMBER(Resultados!F89)),IF(SIGN(D89-F89)=SIGN(Resultados!D89-Resultados!F89),2,0)+IF(D89=Resultados!D89,1,0)+IF(F89=Resultados!F89,1,0)+IF(D89+F89=Resultados!D89+Resultados!F89,1,0),0)
A90: 86 | B90: R32 | C90: Argentina | D90: 3 | E90: X | F90: 0 | G90: Cabo Verde | H90: 2026-07-03 | I90: =H90 | J90: 19:00 | K90: =IF(AND(ISNUMBER(D90),ISNUMBER(F90),ISNUMBER(Resultados!D90),ISNUMBER(Resultados!F90)),IF(SIGN(D90-F90)=SIGN(Resultados!D90-Resultados!F90),2,0)+IF(D90=Resultados!D90,1,0)+IF(F90=Resultados!F90,1,0)+IF(D90+F90=Resultados!D90+Resultados!F90,1,0),0)
A91: 87 | B91: R32 | C91: Colômbia | D91: 2 | E91: X | F91: 1 | G91: Gana | H91: 2026-07-03 | I91: =H91 | J91: 22:30 | K91: =IF(AND(ISNUMBER(D91),ISNUMBER(F91),ISNUMBER(Resultados!D91),ISNUMBER(Resultados!F91)),IF(SIGN(D91-F91)=SIGN(Resultados!D91-Resultados!F91),2,0)+IF(D91=Resultados!D91,1,0)+IF(F91=Resultados!F91,1,0)+IF(D91+F91=Resultados!D91+Resultados!F91,1,0),0)
A92: 88 | B92: R32 | C92: Austrália | D92: 1 | E92: X | F92: 2 | G92: Egito | H92: 2026-07-03 | I92: =H92 | J92: 15:00 | K92: 3
A93: 89 | B93: R16 | C93: Paraguai | D93: 1 | E93: X | F93: 2 | G93: França | H93: 2026-07-04 | I93: =H93 | J93: 18:00 | K93: =IF(AND(ISNUMBER(D93),ISNUMBER(F93),ISNUMBER(Resultados!D93),ISNUMBER(Resultados!F93)),IF(SIGN(D93-F93)=SIGN(Resultados!D93-Resultados!F93),2,0)+IF(D93=Resultados!D93,1,0)+IF(F93=Resultados!F93,1,0)+IF(D93+F93=Resultados!D93+Resultados!F93,1,0),0)
A94: 90 | B94: R16 | C94: Canadá | D94: 1 | E94: X | F94: 2 | G94: Marrocos | H94: 2026-07-04 | I94: =H94 | J94: 14:00 | K94: =IF(AND(ISNUMBER(D94),ISNUMBER(F94),ISNUMBER(Resultados!D94),ISNUMBER(Resultados!F94)),IF(SIGN(D94-F94)=SIGN(Resultados!D94-Resultados!F94),2,0)+IF(D94=Resultados!D94,1,0)+IF(F94=Resultados!F94,1,0)+IF(D94+F94=Resultados!D94+Resultados!F94,1,0),0)
...

Sheet Pedro
A1: COPA 2026 - TABELA DE APOSTAS | F1: Pagamento = Pix | J1: 50 | K1: pago
A2: Nome:
A3: Celular: | D3: e-mail:
A4: JOGOS | B4: GRUPO | H4: DIA | J4: HORA
A5: 1 | B5: A | C5: México | E5: X | G5: África do Sul | H5: 46184 | I5: =H5 | J5: 0.66666667 | K5: =IF(AND(ISNUMBER(D5),ISNUMBER(F5),ISNUMBER(Resultados!D5),ISNUMBER(Resultados!F5)),IF(SIGN(D5-F5)=SIGN(Resultados!D5-Resultados!F5),2,0)+IF(D5=Resultados!D5,1,0)+IF(F5=Resultados!F5,1,0)+IF(D5+F5=Resultados!D5+Resultados!F5,1,0),0)
A6: 2 | B6: A | C6: Coreia do Sul | E6: X | G6: Tchéquia | H6: 46184 | I6: =H6 | J6: 0.95833333 | K6: =IF(AND(ISNUMBER(D6),ISNUMBER(F6),ISNUMBER(Resultados!D6),ISNUMBER(Resultados!F6)),IF(SIGN(D6-F6)=SIGN(Resultados!D6-Resultados!F6),2,0)+IF(D6=Resultados!D6,1,0)+IF(F6=Resultados!F6,1,0)+IF(D6+F6=Resultados!D6+Resultados!F6,1,0),0)
A7: 3 | B7: B | C7: Canadá | E7: X | G7: Bósnia | H7: 46185 | I7: =H7 | J7: 0.66666667 | K7: =IF(AND(ISNUMBER(D7),ISNUMBER(F7),ISNUMBER(Resultados!D7),ISNUMBER(Resultados!F7)),IF(SIGN(D7-F7)=SIGN(Resultados!D7-Resultados!F7),2,0)+IF(D7=Resultados!D7,1,0)+IF(F7=Resultados!F7,1,0)+IF(D7+F7=Resultados!D7+Resultados!F7,1,0),0)
A8: 4 | B8: D | C8: EUA | E8: X | G8: Paraguai | H8: 46185 | I8: =H8 | J8: 0.91666667 | K8: =IF(AND(ISNUMBER(D8),ISNUMBER(F8),ISNUMBER(Resultados!D8),ISNUMBER(Resultados!F8)),IF(SIGN(D8-F8)=SIGN(Resultados!D8-Resultados!F8),2,0)+IF(D8=Resultados!D8,1,0)+IF(F8=Resultados!F8,1,0)+IF(D8+F8=Resultados!D8+Resultados!F8,1,0),0)
A9: 5 | B9: D | C9: Austrália | D9: 1 | E9: X | F9: 2 | G9: Turquia | H9: 46186 | I9: =H9 | J9: 0.041666667 | K9: =IF(AND(ISNUMBER(D9),ISNUMBER(F9),ISNUMBER(Resultados!D9),ISNUMBER(Resultados!F9)),IF(SIGN(D9-F9)=SIGN(Resultados!D9-Resultados!F9),2,0)+IF(D9=Resultados!D9,1,0)+IF(F9=Resultados!F9,1,0)+IF(D9+F9=Resultados!D9+Resultados!F9,1,0),0)
A10: 6 | B10: B | C10: Catar | D10: 0 | E10: X | F10: 2 | G10: Suíça | H10: 46186 | I10: =H10 | J10: 0.66666667 | K10: =IF(AND(ISNUMBER(D10),ISNUMBER(F10),ISNUMBER(Resultados!D10),ISNUMBER(Resultados!F10)),IF(SIGN(D10-F10)=SIGN(Resultados!D10-Resultados!F10),2,0)+IF(D10=Resultados!D10,1,0)+IF(F10=Resultados!F10,1,0)+IF(D10+F10=Resultados!D10+Resultados!F10,1,0),0)
A11: 7 | B11: C | C11: Brasil | D11: 2 | E11: X | F11: 1 | G11: Marrocos | H11: 46186 | I11: =H11 | J11: 0.79166667 | K11: =IF(AND(ISNUMBER(D11),ISNUMBER(F11),ISNUMBER(Resultados!D11),ISNUMBER(Resultados!F11)),IF(SIGN(D11-F11)=SIGN(Resultados!D11-Resultados!F11),2,0)+IF(D11=Resultados!D11,1,0)+IF(F11=Resultados!F11,1,0)+IF(D11+F11=Resultados!D11+Resultados!F11,1,0),0)
A12: 8 | B12: C | C12: Haiti | D12: 0 | E12: X | F12: 4 | G12: Escócia | H12: 46186 | I12: =H12 | J12: 0.91666667 | K12: =IF(AND(ISNUMBER(D12),ISNUMBER(F12),ISNUMBER(Resultados!D12),ISNUMBER(Resultados!F12)),IF(SIGN(D12-F12)=SIGN(Resultados!D12-Resultados!F12),2,0)+IF(D12=Resultados!D12,1,0)+IF(F12=Resultados!F12,1,0)+IF(D12+F12=Resultados!D12+Resultados!F12,1,0),0)
A13: 9 | B13: E | C13: Alemanha | D13: 5 | E13: X | F13: 0 | G13: Curaçau | H13: 46187 | I13: =H13 | J13: 0.58333333 | K13: =IF(AND(ISNUMBER(D13),ISNUMBER(F13),ISNUMBER(Resultados!D13),ISNUMBER(Resultados!F13)),IF(SIGN(D13-F13)=SIGN(Resultados!D13-Resultados!F13),2,0)+IF(D13=Resultados!D13,1,0)+IF(F13=Resultados!F13,1,0)+IF(D13+F13=Resultados!D13+Resultados!F13,1,0),0)
A14: 10 | B14: F | C14: Holanda | D14: 1 | E14: X | F14: 1 | G14: Japão | H14: 46187 | I14: =H14 | J14: 0.70833333 | K14: =IF(AND(ISNUMBER(D14),ISNUMBER(F14),ISNUMBER(Resultados!D14),ISNUMBER(Resultados!F14)),IF(SIGN(D14-F14)=SIGN(Resultados!D14-Resultados!F14),2,0)+IF(D14=Resultados!D14,1,0)+IF(F14=Resultados!F14,1,0)+IF(D14+F14=Resultados!D14+Resultados!F14,1,0),0)
A15: 11 | B15: E | C15: Costa do Marfim | D15: 0 | E15: X | F15: 0 | G15: Equador | H15: 46187 | I15: =H15 | J15: 0.83333333 | K15: =IF(AND(ISNUMBER(D15),ISNUMBER(F15),ISNUMBER(Resultados!D15),ISNUMBER(Resultados!F15)),IF(SIGN(D15-F15)=SIGN(Resultados!D15-Resultados!F15),2,0)+IF(D15=Resultados!D15,1,0)+IF(F15=Resultados!F15,1,0)+IF(D15+F15=Resultados!D15+Resultados!F15,1,0),0)
A16: 12 | B16: F | C16: Suécia | D16: 1 | E16: X | F16: 0 | G16: Tunísia | H16: 46187 | I16: =H16 | J16: 0.95833333 | K16: =IF(AND(ISNUMBER(D16),ISNUMBER(F16),ISNUMBER(Resultados!D16),ISNUMBER(Resultados!F16)),IF(SIGN(D16-F16)=SIGN(Resultados!D16-Resultados!F16),2,0)+IF(D16=Resultados!D16,1,0)+IF(F16=Resultados!F16,1,0)+IF(D16+F16=Resultados!D16+Resultados!F16,1,0),0)
A17: 13 | B17: H | C17: Espanha | D17: 5 | E17: X | F17: 0 | G17: Cabo Verde | H17: 46188 | I17: =H17 | J17: 0.54166667 | K17: =IF(AND(ISNUMBER(D17),ISNUMBER(F17),ISNUMBER(Resultados!D17),ISNUMBER(Resultados!F17)),IF(SIGN(D17-F17)=SIGN(Resultados!D17-Resultados!F17),2,0)+IF(D17=Resultados!D17,1,0)+IF(F17=Resultados!F17,1,0)+IF(D17+F17=Resultados!D17+Resultados!F17,1,0),0)
A18: 14 | B18: G | C18: Bélgica | D18: 2 | E18: X | F18: 1 | G18: Egito | H18: 46188 | I18: =H18 | J18: 0.66666667 | K18: =IF(AND(ISNUMBER(D18),ISNUMBER(F18),ISNUMBER(Resultados!D18),ISNUMBER(Resultados!F18)),IF(SIGN(D18-F18)=SIGN(Resultados!D18-Resultados!F18),2,0)+IF(D18=Resultados!D18,1,0)+IF(F18=Resultados!F18,1,0)+IF(D18+F18=Resultados!D18+Resultados!F18,1,0),0)
A19: 15 | B19: H | C19: Arábia Saudita | D19: 0 | E19: X | F19: 1 | G19: Uruguai | H19: 46188 | I19: =H19 | J19: 0.79166667 | K19: =IF(AND(ISNUMBER(D19),ISNUMBER(F19),ISNUMBER(Resultados!D19),ISNUMBER(Resultados!F19)),IF(SIGN(D19-F19)=SIGN(Resultados!D19-Resultados!F19),2,0)+IF(D19=Resultados!D19,1,0)+IF(F19=Resultados!F19,1,0)+IF(D19+F19=Resultados!D19+Resultados!F19,1,0),0)
A20: 16 | B20: G | C20: Irã | D20: 1 | E20: X | F20: 1 | G20: Nova Zelândia | H20: 46188 | I20: =H20 | J20: 0.91666667 | K20: =IF(AND(ISNUMBER(D20),ISNUMBER(F20),ISNUMBER(Resultados!D20),ISNUMBER(Resultados!F20)),IF(SIGN(D20-F20)=SIGN(Resultados!D20-Resultados!F20),2,0)+IF(D20=Resultados!D20,1,0)+IF(F20=Resultados!F20,1,0)+IF(D20+F20=Resultados!D20+Resultados!F20,1,0),0)
... A76: 72 | B76: K | C76: Colômbia | D76: 1 | E76: X | F76: 2 | G76: Portugal | H76: 46200 | I76: =H76 | J76: 0.91666667 | K76: =IF(AND(ISNUMBER(D76),ISNUMBER(F76),ISNUMBER(Resultados!D76),ISNUMBER(Resultados!F76)),IF(SIGN(D76-F76)=SIGN(Resultados!D76-Resultados!F76),2,0)+IF(D76=Resultados!D76,1,0)+IF(F76=Resultados!F76,1,0)+IF(D76+F76=Resultados!D76+Resultados!F76,1,0),0)
A77: 73 | B77: R32 | C77: África do Sul | D77: 1 | E77: X | F77: 21 | G77: Canadá | H77: 2026-06-28 | I77: =H77 | J77: 16:00 | K77: =IF(AND(ISNUMBER(D77),ISNUMBER(F77),ISNUMBER(Resultados!D77),ISNUMBER(Resultados!F77)),IF(SIGN(D77-F77)=SIGN(Resultados!D77-Resultados!F77),2,0)+IF(D77=Resultados!D77,1,0)+IF(F77=Resultados!F77,1,0)+IF(D77+F77=Resultados!D77+Resultados!F77,1,0),0)
A78: 74 | B78: R32 | C78: Alemanha | D78: 3 | E78: X | F78: 0 | G78: Paraguai | H78: 2026-06-29 | I78: =H78 | J78: 17:30 | K78: 0
A79: 75 | B79: R32 | C79: Holanda | D79: 2 | E79: X | F79: 1 | G79: Marrocos | H79: 2026-06-29 | I79: =H79 | J79: 22:00 | K79: 1
A80: 76 | B80: R32 | C80: Brasil | D80: 2 | E80: X | F80: 0 | G80: Japão | H80: 2026-06-29 | I80: =H80 | J80: 14:00 | K80: =IF(AND(ISNUMBER(D80),ISNUMBER(F80),ISNUMBER(Resultados!D80),ISNUMBER(Resultados!F80)),IF(SIGN(D80-F80)=SIGN(Resultados!D80-Resultados!F80),2,0)+IF(D80=Resultados!D80,1,0)+IF(F80=Resultados!F80,1,0)+IF(D80+F80=Resultados!D80+Resultados!F80,1,0),0)
A81: 77 | B81: R32 | C81: França | D81: 2 | E81: X | F81: 0 | G81: Suécia | H81: 2026-06-30 | I81: =H81 | J81: 18:00 | K81: =IF(AND(ISNUMBER(D81),ISNUMBER(F81),ISNUMBER(Resultados!D81),ISNUMBER(Resultados!F81)),IF(SIGN(D81-F81)=SIGN(Resultados!D81-Resultados!F81),2,0)+IF(D81=Resultados!D81,1,0)+IF(F81=Resultados!F81,1,0)+IF(D81+F81=Resultados!D81+Resultados!F81,1,0),0)
A82: 78 | B82: R32 | C82: Costa do Marfim | D82: 1 | E82: X | F82: 2 | G82: Noruega | H82: 2026-06-30 | I82: =H82 | J82: 14:00 | K82: =IF(AND(ISNUMBER(D82),ISNUMBER(F82),ISNUMBER(Resultados!D82),ISNUMBER(Resultados!F82)),IF(SIGN(D82-F82)=SIGN(Resultados!D82-Resultados!F82),2,0)+IF(D82=Resultados!D82,1,0)+IF(F82=Resultados!F82,1,0)+IF(D82+F82=Resultados!D82+Resultados!F82,1,0),0)
A83: 79 | B83: R32 | C83: México | D83: 1 | E83: X | F83: 0 | G83: Equador | H83: 2026-06-30 | I83: =H83 | J83: 22:00 | K83: =IF(AND(ISNUMBER(D83),ISNUMBER(F83),ISNUMBER(Resultados!D83),ISNUMBER(Resultados!F83)),IF(SIGN(D83-F83)=SIGN(Resultados!D83-Resultados!F83),2,0)+IF(D83=Resultados!D83,1,0)+IF(F83=Resultados!F83,1,0)+IF(D83+F83=Resultados!D83+Resultados!F83,1,0),0)
A84: 80 | B84: R32 | C84: Inglaterra | D84: 3 | E84: X | F84: 0 | G84: RD Congo | H84: 2026-07-01 | I84: =H84 | J84: 13:00 | K84: =IF(AND(ISNUMBER(D84),ISNUMBER(F84),ISNUMBER(Resultados!D84),ISNUMBER(Resultados!F84)),IF(SIGN(D84-F84)=SIGN(Resultados!D84-Resultados!F84),2,0)+IF(D84=Resultados!D84,1,0)+IF(F84=Resultados!F84,1,0)+IF(D84+F84=Resultados!D84+Resultados!F84,1,0),0)
A85: 81 | B85: R32 | C85: EUA | D85: 2 | E85: X | F85: 1 | G85: Bósnia | H85: 2026-07-01 | I85: =H85 | J85: 21:00 | K85: =IF(AND(ISNUMBER(D85),ISNUMBER(F85),ISNUMBER(Resultados!D85),ISNUMBER(Resultados!F85)),IF(SIGN(D85-F85)=SIGN(Resultados!D85-Resultados!F85),2,0)+IF(D85=Resultados!D85,1,0)+IF(F85=Resultados!F85,1,0)+IF(D85+F85=Resultados!D85+Resultados!F85,1,0),0)
A86: 82 | B86: R32 | C86: Bélgica | D86: 1 | E86: X | F86: 2 | G86: Senegal | H86: 2026-07-01 | I86: =H86 | J86: 17:00 | K86: =IF(AND(ISNUMBER(D86),ISNUMBER(F86),ISNUMBER(Resultados!D86),ISNUMBER(Resultados!F86)),IF(SIGN(D86-F86)=SIGN(Resultados!D86-Resultados!F86),2,0)+IF(D86=Resultados!D86,1,0)+IF(F86=Resultados!F86,1,0)+IF(D86+F86=Resultados!D86+Resultados!F86,1,0),0)
A87: 83 | B87: R32 | C87: Portugal | D87: 1 | E87: X | F87: 1 | G87: Croácia | H87: 2026-07-02 | I87: =H87 | J87: 20:00 | K87: =IF(AND(ISNUMBER(D87),ISNUMBER(F87),ISNUMBER(Resultados!D87),ISNUMBER(Resultados!F87)),IF(SIGN(D87-F87)=SIGN(Resultados!D87-Resultados!F87),2,0)+IF(D87=Resultados!D87,1,0)+IF(F87=Resultados!F87,1,0)+IF(D87+F87=Resultados!D87+Resultados!F87,1,0),0)
A88: 84 | B88: R32 | C88: Espanha | D88: 2 | E88: X | F88: 0 | G88: Áustria | H88: 2026-07-02 | I88: =H88 | J88: 16:00 | K88: =IF(AND(ISNUMBER(D88),ISNUMBER(F88),ISNUMBER(Resultados!D88),ISNUMBER(Resultados!F88)),IF(SIGN(D88-F88)=SIGN(Resultados!D88-Resultados!F88),2,0)+IF(D88=Resultados!D88,1,0)+IF(F88=Resultados!F88,1,0)+IF(D88+F88=Resultados!D88+Resultados!F88,1,0),0)
A89: 85 | B89: R32 | C89: Suíça | D89: 1 | E89: X | F89: 0 | G89: Argélia | H89: 2026-07-03 | I89: =H89 | J89: 00:00 | K89: =IF(AND(ISNUMBER(D89),ISNUMBER(F89),ISNUMBER(Resultados!D89),ISNUMBER(Resultados!F89)),IF(SIGN(D89-F89)=SIGN(Resultados!D89-Resultados!F89),2,0)+IF(D89=Resultados!D89,1,0)+IF(F89=Resultados!F89,1,0)+IF(D89+F89=Resultados!D89+Resultados!F89,1,0),0)
A90: 86 | B90: R32 | C90: Argentina | D90: 3 | E90: X | F90: 0 | G90: Cabo Verde | H90: 2026-07-03 | I90: =H90 | J90: 19:00 | K90: =IF(AND(ISNUMBER(D90),ISNUMBER(F90),ISNUMBER(Resultados!D90),ISNUMBER(Resultados!F90)),IF(SIGN(D90-F90)=SIGN(Resultados!D90-Resultados!F90),2,0)+IF(D90=Resultados!D90,1,0)+IF(F90=Resultados!F90,1,0)+IF(D90+F90=Resultados!D90+Resultados!F90,1,0),0)
A91: 87 | B91: R32 | C91: Colômbia | D91: 1 | E91: X | F91: 1 | G91: Gana | H91: 2026-07-03 | I91: =H91 | J91: 22:30 | K91: =IF(AND(ISNUMBER(D91),ISNUMBER(F91),ISNUMBER(Resultados!D91),ISNUMBER(Resultados!F91)),IF(SIGN(D91-F91)=SIGN(Resultados!D91-Resultados!F91),2,0)+IF(D91=Resultados!D91,1,0)+IF(F91=Resultados!F91,1,0)+IF(D91+F91=Resultados!D91+Resultados!F91,1,0),0)
A92: 88 | B92: R32 | C92: Austrália | D92: 1 | E92: X | F92: 1 | G92: Egito | H92: 2026-07-03 | I92: =H92 | J92: 15:00 | K92: 5
A93: 89 | B93: R16 | C93: Paraguai | D93: 0 | E93: X | F93: 2 | G93: França | H93: 2026-07-04 | I93: =H93 | J93: 18:00 | K93: =IF(AND(ISNUMBER(D93),ISNUMBER(F93),ISNUMBER(Resultados!D93),ISNUMBER(Resultados!F93)),IF(SIGN(D93-F93)=SIGN(Resultados!D93-Resultados!F93),2,0)+IF(D93=Resultados!D93,1,0)+IF(F93=Resultados!F93,1,0)+IF(D93+F93=Resultados!D93+Resultados!F93,1,0),0)
A94: 90 | B94: R16 | C94: Canadá | D94: 1 | E94: X | F94: 2 | G94: Marrocos | H94: 2026-07-04 | I94: =H94 | J94: 14:00 | K94: =IF(AND(ISNUMBER(D94),ISNUMBER(F94),ISNUMBER(Resultados!D94),ISNUMBER(Resultados!F94)),IF(SIGN(D94-F94)=SIGN(Resultados!D94-Resultados!F94),2,0)+IF(D94=Resultados!D94,1,0)+IF(F94=Resultados!F94,1,0)+IF(D94+F94=Resultados!D94+Resultados!F94,1,0),0)
A95: 91 | B95: R16 | C95: Brasil | D95: 2 | E95: X | F95: 1 | G95: Noruega | H95: 2026-07-05 | I95: =H95 | J95: 17:00 | K95: =IF(AND(ISNUMBER(D95),ISNUMBER(F95),ISNUMBER(Resultados!D95),ISNUMBER(Resultados!F95)),IF(SIGN(D95-F95)=SIGN(Resultados!D95-Resultados!F95),2,0)+IF(D95=Resultados!D95,1,0)+IF(F95=Resultados!F95,1,0)+IF(D95+F95=Resultados!D95+Resultados!F95,1,0),0)
...

Sheet Mauro
A1: COPA 2026 - TABELA DE APOSTAS | F1: Pagamento = Pix | J1: 50 | K1: pago
A2: Nome:
A3: Celular: | D3: e-mail:
A4: JOGOS | B4: GRUPO | H4: DIA | J4: HORA
A5: 1 | B5: A | C5: México | D5: 2 | E5: X | F5: 0 | G5: África do Sul | H5: 46184 | I5: =H5 | J5: 0.66666667 | K5: =IF(AND(ISNUMBER(D5),ISNUMBER(F5),ISNUMBER(Resultados!D5),ISNUMBER(Resultados!F5)),IF(SIGN(D5-F5)=SIGN(Resultados!D5-Resultados!F5),2,0)+IF(D5=Resultados!D5,1,0)+IF(F5=Resultados!F5,1,0)+IF(D5+F5=Resultados!D5+Resultados!F5,1,0),0)
A6: 2 | B6: A | C6: Coreia do Sul | D6: 1 | E6: X | F6: 1 | G6: Tchéquia | H6: 46184 | I6: =H6 | J6: 0.95833333 | K6: =IF(AND(ISNUMBER(D6),ISNUMBER(F6),ISNUMBER(Resultados!D6),ISNUMBER(Resultados!F6)),IF(SIGN(D6-F6)=SIGN(Resultados!D6-Resultados!F6),2,0)+IF(D6=Resultados!D6,1,0)+IF(F6=Resultados!F6,1,0)+IF(D6+F6=Resultados!D6+Resultados!F6,1,0),0)
A7: 3 | B7: B | C7: Canadá | D7: 0 | E7: X | F7: 1 | G7: Bósnia | H7: 46185 | I7: =H7 | J7: 0.66666667 | K7: =IF(AND(ISNUMBER(D7),ISNUMBER(F7),ISNUMBER(Resultados!D7),ISNUMBER(Resultados!F7)),IF(SIGN(D7-F7)=SIGN(Resultados!D7-Resultados!F7),2,0)+IF(D7=Resultados!D7,1,0)+IF(F7=Resultados!F7,1,0)+IF(D7+F7=Resultados!D7+Resultados!F7,1,0),0)
A8: 4 | B8: D | C8: EUA | D8: 3 | E8: X | F8: 1 | G8: Paraguai | H8: 46185 | I8: =H8 | J8: 0.91666667 | K8: =IF(AND(ISNUMBER(D8),ISNUMBER(F8),ISNUMBER(Resultados!D8),ISNUMBER(Resultados!F8)),IF(SIGN(D8-F8)=SIGN(Resultados!D8-Resultados!F8),2,0)+IF(D8=Resultados!D8,1,0)+IF(F8=Resultados!F8,1,0)+IF(D8+F8=Resultados!D8+Resultados!F8,1,0),0)
A9: 5 | B9: D | C9: Austrália | D9: 0 | E9: X | F9: 2 | G9: Turquia | H9: 46186 | I9: =H9 | J9: 0.041666667 | K9: =IF(AND(ISNUMBER(D9),ISNUMBER(F9),ISNUMBER(Resultados!D9),ISNUMBER(Resultados!F9)),IF(SIGN(D9-F9)=SIGN(Resultados!D9-Resultados!F9),2,0)+IF(D9=Resultados!D9,1,0)+IF(F9=Resultados!F9,1,0)+IF(D9+F9=Resultados!D9+Resultados!F9,1,0),0)
A10: 6 | B10: B | C10: Catar | D10: 0 | E10: X | F10: 3 | G10: Suíça | H10: 46186 | I10: =H10 | J10: 0.66666667 | K10: =IF(AND(ISNUMBER(D10),ISNUMBER(F10),ISNUMBER(Resultados!D10),ISNUMBER(Resultados!F10)),IF(SIGN(D10-F10)=SIGN(Resultados!D10-Resultados!F10),2,0)+IF(D10=Resultados!D10,1,0)+IF(F10=Resultados!F10,1,0)+IF(D10+F10=Resultados!D10+Resultados!F10,1,0),0)
A11: 7 | B11: C | C11: Brasil | D11: 1 | E11: X | F11: 2 | G11: Marrocos | H11: 46186 | I11: =H11 | J11: 0.79166667 | K11: =IF(AND(ISNUMBER(D11),ISNUMBER(F11),ISNUMBER(Resultados!D11),ISNUMBER(Resultados!F11)),IF(SIGN(D11-F11)=SIGN(Resultados!D11-Resultados!F11),2,0)+IF(D11=Resultados!D11,1,0)+IF(F11=Resultados!F11,1,0)+IF(D11+F11=Resultados!D11+Resultados!F11,1,0),0)
A12: 8 | B12: C | C12: Haiti | D12: 0 | E12: X | F12: 3 | G12: Escócia | H12: 46186 | I12: =H12 | J12: 0.91666667 | K12: =IF(AND(ISNUMBER(D12),ISNUMBER(F12),ISNUMBER(Resultados!D12),ISNUMBER(Resultados!F12)),IF(SIGN(D12-F12)=SIGN(Resultados!D12-Resultados!F12),2,0)+IF(D12=Resultados!D12,1,0)+IF(F12=Resultados!F12,1,0)+IF(D12+F12=Resultados!D12+Resultados!F12,1,0),0)
A13: 9 | B13: E | C13: Alemanha | D13: 7 | E13: X | F13: 0 | G13: Curaçau | H13: 46187 | I13: =H13 | J13: 0.58333333 | K13: =IF(AND(ISNUMBER(D13),ISNUMBER(F13),ISNUMBER(Resultados!D13),ISNUMBER(Resultados!F13)),IF(SIGN(D13-F13)=SIGN(Resultados!D13-Resultados!F13),2,0)+IF(D13=Resultados!D13,1,0)+IF(F13=Resultados!F13,1,0)+IF(D13+F13=Resultados!D13+Resultados!F13,1,0),0)
A14: 10 | B14: F | C14: Holanda | D14: 2 | E14: X | F14: 1 | G14: Japão | H14: 46187 | I14: =H14 | J14: 0.70833333 | K14: =IF(AND(ISNUMBER(D14),ISNUMBER(F14),ISNUMBER(Resultados!D14),ISNUMBER(Resultados!F14)),IF(SIGN(D14-F14)=SIGN(Resultados!D14-Resultados!F14),2,0)+IF(D14=Resultados!D14,1,0)+IF(F14=Resultados!F14,1,0)+IF(D14+F14=Resultados!D14+Resultados!F14,1,0),0)
A15: 11 | B15: E | C15: Costa do Marfim | D15: 1 | E15: X | F15: 1 | G15: Equador | H15: 46187 | I15: =H15 | J15: 0.83333333 | K15: =IF(AND(ISNUMBER(D15),ISNUMBER(F15),ISNUMBER(Resultados!D15),ISNUMBER(Resultados!F15)),IF(SIGN(D15-F15)=SIGN(Resultados!D15-Resultados!F15),2,0)+IF(D15=Resultados!D15,1,0)+IF(F15=Resultados!F15,1,0)+IF(D15+F15=Resultados!D15+Resultados!F15,1,0),0)
A16: 12 | B16: F | C16: Suécia | D16: 1 | E16: X | F16: 1 | G16: Tunísia | H16: 46187 | I16: =H16 | J16: 0.95833333 | K16: =IF(AND(ISNUMBER(D16),ISNUMBER(F16),ISNUMBER(Resultados!D16),ISNUMBER(Resultados!F16)),IF(SIGN(D16-F16)=SIGN(Resultados!D16-Resultados!F16),2,0)+IF(D16=Resultados!D16,1,0)+IF(F16=Resultados!F16,1,0)+IF(D16+F16=Resultados!D16+Resultados!F16,1,0),0)
... A76: 72 | B76: K | C76: Colômbia | D76: 1 | E76: X | F76: 2 | G76: Portugal | H76: 46200 | I76: =H76 | J76: 0.91666667 | K76: =IF(AND(ISNUMBER(D76),ISNUMBER(F76),ISNUMBER(Resultados!D76),ISNUMBER(Resultados!F76)),IF(SIGN(D76-F76)=SIGN(Resultados!D76-Resultados!F76),2,0)+IF(D76=Resultados!D76,1,0)+IF(F76=Resultados!F76,1,0)+IF(D76+F76=Resultados!D76+Resultados!F76,1,0),0)
A77: 73 | B77: R32 | C77: África do Sul | D77: 0 | E77: X | F77: 1 | G77: Canadá | H77: 2026-06-28 | I77: =H77 | J77: 16:00 | K77: =IF(AND(ISNUMBER(D77),ISNUMBER(F77),ISNUMBER(Resultados!D77),ISNUMBER(Resultados!F77)),IF(SIGN(D77-F77)=SIGN(Resultados!D77-Resultados!F77),2,0)+IF(D77=Resultados!D77,1,0)+IF(F77=Resultados!F77,1,0)+IF(D77+F77=Resultados!D77+Resultados!F77,1,0),0)
A78: 74 | B78: R32 | C78: Alemanha | D78: 2 | E78: X | F78: 0 | G78: Paraguai | H78: 2026-06-29 | I78: =H78 | J78: 17:30 | K78: 1
A79: 75 | B79: R32 | C79: Holanda | D79: 3 | E79: X | F79: 1 | G79: Marrocos | H79: 2026-06-29 | I79: =H79 | J79: 22:00 | K79: 1
A80: 76 | B80: R32 | C80: Brasil | D80: 2 | E80: X | F80: 0 | G80: Japão | H80: 2026-06-29 | I80: =H80 | J80: 14:00 | K80: =IF(AND(ISNUMBER(D80),ISNUMBER(F80),ISNUMBER(Resultados!D80),ISNUMBER(Resultados!F80)),IF(SIGN(D80-F80)=SIGN(Resultados!D80-Resultados!F80),2,0)+IF(D80=Resultados!D80,1,0)+IF(F80=Resultados!F80,1,0)+IF(D80+F80=Resultados!D80+Resultados!F80,1,0),0)
A81: 77 | B81: R32 | C81: França | D81: 4 | E81: X | F81: 1 | G81: Suécia | H81: 2026-06-30 | I81: =H81 | J81: 18:00 | K81: =IF(AND(ISNUMBER(D81),ISNUMBER(F81),ISNUMBER(Resultados!D81),ISNUMBER(Resultados!F81)),IF(SIGN(D81-F81)=SIGN(Resultados!D81-Resultados!F81),2,0)+IF(D81=Resultados!D81,1,0)+IF(F81=Resultados!F81,1,0)+IF(D81+F81=Resultados!D81+Resultados!F81,1,0),0)
A82: 78 | B82: R32 | C82: Costa do Marfim | D82: 0 | E82: X | F82: 3 | G82: Noruega | H82: 2026-06-30 | I82: =H82 | J82: 14:00 | K82: =IF(AND(ISNUMBER(D82),ISNUMBER(F82),ISNUMBER(Resultados!D82),ISNUMBER(Resultados!F82)),IF(SIGN(D82-F82)=SIGN(Resultados!D82-Resultados!F82),2,0)+IF(D82=Resultados!D82,1,0)+IF(F82=Resultados!F82,1,0)+IF(D82+F82=Resultados!D82+Resultados!F82,1,0),0)
A83: 79 | B83: R32 | C83: México | D83: 2 | E83: X | F83: 1 | G83: Equador | H83: 2026-06-30 | I83: =H83 | J83: 22:00 | K83: =IF(AND(ISNUMBER(D83),ISNUMBER(F83),ISNUMBER(Resultados!D83),ISNUMBER(Resultados!F83)),IF(SIGN(D83-F83)=SIGN(Resultados!D83-Resultados!F83),2,0)+IF(D83=Resultados!D83,1,0)+IF(F83=Resultados!F83,1,0)+IF(D83+F83=Resultados!D83+Resultados!F83,1,0),0)
A84: 80 | B84: R32 | C84: Inglaterra | D84: 3 | E84: X | F84: 1 | G84: RD Congo | H84: 2026-07-01 | I84: =H84 | J84: 13:00 | K84: =IF(AND(ISNUMBER(D84),ISNUMBER(F84),ISNUMBER(Resultados!D84),ISNUMBER(Resultados!F84)),IF(SIGN(D84-F84)=SIGN(Resultados!D84-Resultados!F84),2,0)+IF(D84=Resultados!D84,1,0)+IF(F84=Resultados!F84,1,0)+IF(D84+F84=Resultados!D84+Resultados!F84,1,0),0)
A85: 81 | B85: R32 | C85: EUA | D85: 4 | E85: X | F85: 0 | G85: Bósnia | H85: 2026-07-01 | I85: =H85 | J85: 21:00 | K85: =IF(AND(ISNUMBER(D85),ISNUMBER(F85),ISNUMBER(Resultados!D85),ISNUMBER(Resultados!F85)),IF(SIGN(D85-F85)=SIGN(Resultados!D85-Resultados!F85),2,0)+IF(D85=Resultados!D85,1,0)+IF(F85=Resultados!F85,1,0)+IF(D85+F85=Resultados!D85+Resultados!F85,1,0),0)
A86: 82 | B86: R32 | C86: Bélgica | D86: 1 | E86: X | F86: 2 | G86: Senegal | H86: 2026-07-01 | I86: =H86 | J86: 17:00 | K86: =IF(AND(ISNUMBER(D86),ISNUMBER(F86),ISNUMBER(Resultados!D86),ISNUMBER(Resultados!F86)),IF(SIGN(D86-F86)=SIGN(Resultados!D86-Resultados!F86),2,0)+IF(D86=Resultados!D86,1,0)+IF(F86=Resultados!F86,1,0)+IF(D86+F86=Resultados!D86+Resultados!F86,1,0),0)
A87: 83 | B87: R32 | C87: Portugal | D87: 1 | E87: X | F87: 1 | G87: Croácia | H87: 2026-07-02 | I87: =H87 | J87: 20:00 | K87: =IF(AND(ISNUMBER(D87),ISNUMBER(F87),ISNUMBER(Resultados!D87),ISNUMBER(Resultados!F87)),IF(SIGN(D87-F87)=SIGN(Resultados!D87-Resultados!F87),2,0)+IF(D87=Resultados!D87,1,0)+IF(F87=Resultados!F87,1,0)+IF(D87+F87=Resultados!D87+Resultados!F87,1,0),0)
A88: 84 | B88: R32 | C88: Espanha | D88: 2 | E88: X | F88: 0 | G88: Áustria | H88: 2026-07-02 | I88: =H88 | J88: 16:00 | K88: =IF(AND(ISNUMBER(D88),ISNUMBER(F88),ISNUMBER(Resultados!D88),ISNUMBER(Resultados!F88)),IF(SIGN(D88-F88)=SIGN(Resultados!D88-Resultados!F88),2,0)+IF(D88=Resultados!D88,1,0)+IF(F88=Resultados!F88,1,0)+IF(D88+F88=Resultados!D88+Resultados!F88,1,0),0)
A89: 85 | B89: R32 | C89: Suíça | D89: 3 | E89: X | F89: 1 | G89: Argélia | H89: 2026-07-03 | I89: =H89 | J89: 00:00 | K89: =IF(AND(ISNUMBER(D89),ISNUMBER(F89),ISNUMBER(Resultados!D89),ISNUMBER(Resultados!F89)),IF(SIGN(D89-F89)=SIGN(Resultados!D89-Resultados!F89),2,0)+IF(D89=Resultados!D89,1,0)+IF(F89=Resultados!F89,1,0)+IF(D89+F89=Resultados!D89+Resultados!F89,1,0),0)
A90: 86 | B90: R32 | C90: Argentina | D90: 4 | E90: X | F90: 0 | G90: Cabo Verde | H90: 2026-07-03 | I90: =H90 | J90: 19:00 | K90: =IF(AND(ISNUMBER(D90),ISNUMBER(F90),ISNUMBER(Resultados!D90),ISNUMBER(Resultados!F90)),IF(SIGN(D90-F90)=SIGN(Resultados!D90-Resultados!F90),2,0)+IF(D90=Resultados!D90,1,0)+IF(F90=Resultados!F90,1,0)+IF(D90+F90=Resultados!D90+Resultados!F90,1,0),0)
A91: 87 | B91: R32 | C91: Colômbia | D91: 3 | E91: X | F91: 0 | G91: Gana | H91: 2026-07-03 | I91: =H91 | J91: 22:30 | K91: =IF(AND(ISNUMBER(D91),ISNUMBER(F91),ISNUMBER(Resultados!D91),ISNUMBER(Resultados!F91)),IF(SIGN(D91-F91)=SIGN(Resultados!D91-Resultados!F91),2,0)+IF(D91=Resultados!D91,1,0)+IF(F91=Resultados!F91,1,0)+IF(D91+F91=Resultados!D91+Resultados!F91,1,0),0)
A92: 88 | B92: R32 | C92: Austrália | D92: 1 | E92: X | F92: 1 | G92: Egito | H92: 2026-07-03 | I92: =H92 | J92: 15:00 | K92: 5
A93: 89 | B93: R16 | C93: Paraguai | D93: 0 | E93: X | F93: 4 | G93: França | H93: 2026-07-04 | I93: =H93 | J93: 18:00 | K93: =IF(AND(ISNUMBER(D93),ISNUMBER(F93),ISNUMBER(Resultados!D93),ISNUMBER(Resultados!F93)),IF(SIGN(D93-F93)=SIGN(Resultados!D93-Resultados!F93),2,0)+IF(D93=Resultados!D93,1,0)+IF(F93=Resultados!F93,1,0)+IF(D93+F93=Resultados!D93+Resultados!F93,1,0),0)
A94: 90 | B94: R16 | C94: Canadá | D94: 0 | E94: X | F94: 2 | G94: Marrocos | H94: 2026-07-04 | I94: =H94 | J94: 14:00 | K94: =IF(AND(ISNUMBER(D94),ISNUMBER(F94),ISNUMBER(Resultados!D94),ISNUMBER(Resultados!F94)),IF(SIGN(D94-F94)=SIGN(Resultados!D94-Resultados!F94),2,0)+IF(D94=Resultados!D94,1,0)+IF(F94=Resultados!F94,1,0)+IF(D94+F94=Resultados!D94+Resultados!F94,1,0),0)
A95: 91 | B95: R16 | C95: Brasil | D95: 2 | E95: X | F95: 1 | G95: Noruega | H95: 2026-07-05 | I95: =H95 | J95: 17:00 | K95: =IF(AND(ISNUMBER(D95),ISNUMBER(F95),ISNUMBER(Resultados!D95),ISNUMBER(Resultados!F95)),IF(SIGN(D95-F95)=SIGN(Resultados!D95-Resultados!F95),2,0)+IF(D95=Resultados!D95,1,0)+IF(F95=Resultados!F95,1,0)+IF(D95+F95=Resultados!D95+Resultados!F95,1,0),0)
A96: 92 | B96: R16 | C96: México | D96: 2 | E96: X | F96: 1 | G96: Inglaterra | H96: 2026-07-05 | I96: =H96 | J96: 21:00 | K96: =IF(AND(ISNUMBER(D96),ISNUMBER(F96),ISNUMBER(Resultados!D96),ISNUMBER(Resultados!F96)),IF(SIGN(D96-F96)=SIGN(Resultados!D96-Resultados!F96),2,0)+IF(D96=Resultados!D96,1,0)+IF(F96=Resultados!F96,1,0)+IF(D96+F96=Resultados!D96+Resultados!F96,1,0),0)
A97: 93 | B97: R16 | C97: Portugal | D97: 1 | E97: X | F97: 2 | G97: Espanha | H97: 2026-07-06 | I97: =H97 | J97: 16:00 | K97: =IF(AND(ISNUMBER(D97),ISNUMBER(F97),ISNUMBER(Resultados!D97),ISNUMBER(Resultados!F97)),IF(SIGN(D97-F97)=SIGN(Resultados!D97-Resultados!F97),2,0)+IF(D97=Resultados!D97,1,0)+IF(F97=Resultados!F97,1,0)+IF(D97+F97=Resultados!D97+Resultados!F97,1,0),0)
A98: 94 | B98: R16 | C98: EUA | D98: 3 | E98: X | F98: 1 | G98: Bélgica | H98: 2026-07-06 | I98: =H98 | J98: 21:00 | K98: =IF(AND(ISNUMBER(D98),ISNUMBER(F98),ISNUMBER(Resultados!D98),ISNUMBER(Resultados!F98)),IF(SIGN(D98-F98)=SIGN(Resultados!D98-Resultados!F98),2,0)+IF(D98=Resultados!D98,1,0)+IF(F98=Resultados!F98,1,0)+IF(D98+F98=Resultados!D98+Resultados!F98,1,0),0)
A99: 95 | B99: R16 | C99: Argentina | D99: 3 | E99: X | F99: 0 | G99: Egito | H99: 2026-07-07 | I99: =H99 | J99: 13:00 | K99: =IF(AND(ISNUMBER(D99),ISNUMBER(F99),ISNUMBER(Resultados!D99),ISNUMBER(Resultados!F99)),IF(SIGN(D99-F99)=SIGN(Resultados!D99-Resultados!F99),2,0)+IF(D99=Resultados!D99,1,0)+IF(F99=Resultados!F99,1,0)+IF(D99+F99=Resultados!D99+Resultados!F99,1,0),0)
...

Sheet Rodrigo
A1: COPA 2026 - TABELA DE APOSTAS | F1: Pagamento = Pix | J1: 50
A2: Nome:
A3: Celular: | D3: e-mail:
A4: JOGOS | B4: GRUPO | H4: DIA | J4: HORA
A5: 1 | B5: A | C5: México | D5: 2 | E5: X | F5: 0 | G5: África do Sul | H5: 46184 | I5: =H5 | J5: 0.66666667 | K5: =IF(AND(ISNUMBER(D5),ISNUMBER(F5),ISNUMBER(Resultados!D5),ISNUMBER(Resultados!F5)),IF(SIGN(D5-F5)=SIGN(Resultados!D5-Resultados!F5),2,0)+IF(D5=Resultados!D5,1,0)+IF(F5=Resultados!F5,1,0)+IF(D5+F5=Resultados!D5+Resultados!F5,1,0),0)
A6: 2 | B6: A | C6: Coreia do Sul | D6: 2 | E6: X | F6: 1 | G6: Tchéquia | H6: 46184 | I6: =H6 | J6: 0.95833333 | K6: =IF(AND(ISNUMBER(D6),ISNUMBER(F6),ISNUMBER(Resultados!D6),ISNUMBER(Resultados!F6)),IF(SIGN(D6-F6)=SIGN(Resultados!D6-Resultados!F6),2,0)+IF(D6=Resultados!D6,1,0)+IF(F6=Resultados!F6,1,0)+IF(D6+F6=Resultados!D6+Resultados!F6,1,0),0)
A7: 3 | B7: B | C7: Canadá | D7: 1 | E7: X | F7: 0 | G7: Bósnia | H7: 46185 | I7: =H7 | J7: 0.66666667 | K7: =IF(AND(ISNUMBER(D7),ISNUMBER(F7),ISNUMBER(Resultados!D7),ISNUMBER(Resultados!F7)),IF(SIGN(D7-F7)=SIGN(Resultados!D7-Resultados!F7),2,0)+IF(D7=Resultados!D7,1,0)+IF(F7=Resultados!F7,1,0)+IF(D7+F7=Resultados!D7+Resultados!F7,1,0),0)
A8: 4 | B8: D | C8: EUA | D8: 2 | E8: X | F8: 1 | G8: Paraguai | H8: 46185 | I8: =H8 | J8: 0.91666667 | K8: =IF(AND(ISNUMBER(D8),ISNUMBER(F8),ISNUMBER(Resultados!D8),ISNUMBER(Resultados!F8)),IF(SIGN(D8-F8)=SIGN(Resultados!D8-Resultados!F8),2,0)+IF(D8=Resultados!D8,1,0)+IF(F8=Resultados!F8,1,0)+IF(D8+F8=Resultados!D8+Resultados!F8,1,0),0)
A9: 5 | B9: D | C9: Austrália | D9: 1 | E9: X | F9: 2 | G9: Turquia | H9: 46186 | I9: =H9 | J9: 0.041666667 | K9: =IF(AND(ISNUMBER(D9),ISNUMBER(F9),ISNUMBER(Resultados!D9),ISNUMBER(Resultados!F9)),IF(SIGN(D9-F9)=SIGN(Resultados!D9-Resultados!F9),2,0)+IF(D9=Resultados!D9,1,0)+IF(F9=Resultados!F9,1,0)+IF(D9+F9=Resultados!D9+Resultados!F9,1,0),0)
A10: 6 | B10: B | C10: Catar | D10: 0 | E10: X | F10: 2 | G10: Suíça | H10: 46186 | I10: =H10 | J10: 0.66666667 | K10: =IF(AND(ISNUMBER(D10),ISNUMBER(F10),ISNUMBER(Resultados!D10),ISNUMBER(Resultados!F10)),IF(SIGN(D10-F10)=SIGN(Resultados!D10-Resultados!F10),2,0)+IF(D10=Resultados!D10,1,0)+IF(F10=Resultados!F10,1,0)+IF(D10+F10=Resultados!D10+Resultados!F10,1,0),0)
A11: 7 | B11: C | C11: Brasil | D11: 2 | E11: X | F11: 1 | G11: Marrocos | H11: 46186 | I11: =H11 | J11: 0.79166667 | K11: =IF(AND(ISNUMBER(D11),ISNUMBER(F11),ISNUMBER(Resultados!D11),ISNUMBER(Resultados!F11)),IF(SIGN(D11-F11)=SIGN(Resultados!D11-Resultados!F11),2,0)+IF(D11=Resultados!D11,1,0)+IF(F11=Resultados!F11,1,0)+IF(D11+F11=Resultados!D11+Resultados!F11,1,0),0)
A12: 8 | B12: C | C12: Haiti | D12: 0 | E12: X | F12: 2 | G12: Escócia | H12: 46186 | I12: =H12 | J12: 0.91666667 | K12: =IF(AND(ISNUMBER(D12),ISNUMBER(F12),ISNUMBER(Resultados!D12),ISNUMBER(Resultados!F12)),IF(SIGN(D12-F12)=SIGN(Resultados!D12-Resultados!F12),2,0)+IF(D12=Resultados!D12,1,0)+IF(F12=Resultados!F12,1,0)+IF(D12+F12=Resultados!D12+Resultados!F12,1,0),0)
A13: 9 | B13: E | C13: Alemanha | D13: 5 | E13: X | F13: 0 | G13: Curaçau | H13: 46187 | I13: =H13 | J13: 0.58333333 | K13: =IF(AND(ISNUMBER(D13),ISNUMBER(F13),ISNUMBER(Resultados!D13),ISNUMBER(Resultados!F13)),IF(SIGN(D13-F13)=SIGN(Resultados!D13-Resultados!F13),2,0)+IF(D13=Resultados!D13,1,0)+IF(F13=Resultados!F13,1,0)+IF(D13+F13=Resultados!D13+Resultados!F13,1,0),0)
A14: 10 | B14: F | C14: Holanda | D14: 2 | E14: X | F14: 1 | G14: Japão | H14: 46187 | I14: =H14 | J14: 0.70833333 | K14: =IF(AND(ISNUMBER(D14),ISNUMBER(F14),ISNUMBER(Resultados!D14),ISNUMBER(Resultados!F14)),IF(SIGN(D14-F14)=SIGN(Resultados!D14-Resultados!F14),2,0)+IF(D14=Resultados!D14,1,0)+IF(F14=Resultados!F14,1,0)+IF(D14+F14=Resultados!D14+Resultados!F14,1,0),0)
A15: 11 | B15: E | C15: Costa do Marfim | D15: 1 | E15: X | F15: 1 | G15: Equador | H15: 46187 | I15: =H15 | J15: 0.83333333 | K15: =IF(AND(ISNUMBER(D15),ISNUMBER(F15),ISNUMBER(Resultados!D15),ISNUMBER(Resultados!F15)),IF(SIGN(D15-F15)=SIGN(Resultados!D15-Resultados!F15),2,0)+IF(D15=Resultados!D15,1,0)+IF(F15=Resultados!F15,1,0)+IF(D15+F15=Resultados!D15+Resultados!F15,1,0),0)
A16: 12 | B16: F | C16: Suécia | D16: 1 | E16: X | F16: 1 | G16: Tunísia | H16: 46187 | I16: =H16 | J16: 0.95833333 | K16: =IF(AND(ISNUMBER(D16),ISNUMBER(F16),ISNUMBER(Resultados!D16),ISNUMBER(Resultados!F16)),IF(SIGN(D16-F16)=SIGN(Resultados!D16-Resultados!F16),2,0)+IF(D16=Resultados!D16,1,0)+IF(F16=Resultados!F16,1,0)+IF(D16+F16=Resultados!D16+Resultados!F16,1,0),0)
... A76: 72 | B76: K | C76: Colômbia | D76: 1 | E76: X | F76: 1 | G76: Portugal | H76: 46200 | I76: =H76 | J76: 0.91666667 | K76: =IF(AND(ISNUMBER(D76),ISNUMBER(F76),ISNUMBER(Resultados!D76),ISNUMBER(Resultados!F76)),IF(SIGN(D76-F76)=SIGN(Resultados!D76-Resultados!F76),2,0)+IF(D76=Resultados!D76,1,0)+IF(F76=Resultados!F76,1,0)+IF(D76+F76=Resultados!D76+Resultados!F76,1,0),0)
A77: 73 | B77: R32 | C77: África do Sul | D77: 0 | E77: X | F77: 2 | G77: Canadá | H77: 2026-06-28 | I77: =H77 | J77: 16:00 | K77: =IF(AND(ISNUMBER(D77),ISNUMBER(F77),ISNUMBER(Resultados!D77),ISNUMBER(Resultados!F77)),IF(SIGN(D77-F77)=SIGN(Resultados!D77-Resultados!F77),2,0)+IF(D77=Resultados!D77,1,0)+IF(F77=Resultados!F77,1,0)+IF(D77+F77=Resultados!D77+Resultados!F77,1,0),0)
A78: 74 | B78: R32 | C78: Alemanha | D78: 2 | E78: X | F78: 1 | G78: Paraguai | H78: 2026-06-29 | I78: =H78 | J78: 17:30 | K78: 1
A79: 75 | B79: R32 | C79: Holanda | D79: 2 | E79: X | F79: 1 | G79: Marrocos | H79: 2026-06-29 | I79: =H79 | J79: 22:00 | K79: 1
A80: 76 | B80: R32 | C80: Brasil | D80: 2 | E80: X | F80: 1 | G80: Japão | H80: 2026-06-29 | I80: =H80 | J80: 14:00 | K80: =IF(AND(ISNUMBER(D80),ISNUMBER(F80),ISNUMBER(Resultados!D80),ISNUMBER(Resultados!F80)),IF(SIGN(D80-F80)=SIGN(Resultados!D80-Resultados!F80),2,0)+IF(D80=Resultados!D80,1,0)+IF(F80=Resultados!F80,1,0)+IF(D80+F80=Resultados!D80+Resultados!F80,1,0),0)
A81: 77 | B81: R32 | C81: França | D81: 2 | E81: X | F81: 0 | G81: Suécia | H81: 2026-06-30 | I81: =H81 | J81: 18:00 | K81: =IF(AND(ISNUMBER(D81),ISNUMBER(F81),ISNUMBER(Resultados!D81),ISNUMBER(Resultados!F81)),IF(SIGN(D81-F81)=SIGN(Resultados!D81-Resultados!F81),2,0)+IF(D81=Resultados!D81,1,0)+IF(F81=Resultados!F81,1,0)+IF(D81+F81=Resultados!D81+Resultados!F81,1,0),0)
A82: 78 | B82: R32 | C82: Costa do Marfim | D82: 1 | E82: X | F82: 1 | G82: Noruega | H82: 2026-06-30 | I82: =H82 | J82: 14:00 | K82: =IF(AND(ISNUMBER(D82),ISNUMBER(F82),ISNUMBER(Resultados!D82),ISNUMBER(Resultados!F82)),IF(SIGN(D82-F82)=SIGN(Resultados!D82-Resultados!F82),2,0)+IF(D82=Resultados!D82,1,0)+IF(F82=Resultados!F82,1,0)+IF(D82+F82=Resultados!D82+Resultados!F82,1,0),0)
A83: 79 | B83: R32 | C83: México | D83: 1 | E83: X | F83: 0 | G83: Equador | H83: 2026-06-30 | I83: =H83 | J83: 22:00 | K83: =IF(AND(ISNUMBER(D83),ISNUMBER(F83),ISNUMBER(Resultados!D83),ISNUMBER(Resultados!F83)),IF(SIGN(D83-F83)=SIGN(Resultados!D83-Resultados!F83),2,0)+IF(D83=Resultados!D83,1,0)+IF(F83=Resultados!F83,1,0)+IF(D83+F83=Resultados!D83+Resultados!F83,1,0),0)
A84: 80 | B84: R32 | C84: Inglaterra | D84: 2 | E84: X | F84: 0 | G84: RD Congo | H84: 2026-07-01 | I84: =H84 | J84: 13:00 | K84: =IF(AND(ISNUMBER(D84),ISNUMBER(F84),ISNUMBER(Resultados!D84),ISNUMBER(Resultados!F84)),IF(SIGN(D84-F84)=SIGN(Resultados!D84-Resultados!F84),2,0)+IF(D84=Resultados!D84,1,0)+IF(F84=Resultados!F84,1,0)+IF(D84+F84=Resultados!D84+Resultados!F84,1,0),0)
A85: 81 | B85: R32 | C85: EUA | D85: 2 | E85: X | F85: 1 | G85: Bósnia | H85: 2026-07-01 | I85: =H85 | J85: 21:00 | K85: =IF(AND(ISNUMBER(D85),ISNUMBER(F85),ISNUMBER(Resultados!D85),ISNUMBER(Resultados!F85)),IF(SIGN(D85-F85)=SIGN(Resultados!D85-Resultados!F85),2,0)+IF(D85=Resultados!D85,1,0)+IF(F85=Resultados!F85,1,0)+IF(D85+F85=Resultados!D85+Resultados!F85,1,0),0)
A86: 82 | B86: R32 | C86: Bélgica | D86: 2 | E86: X | F86: 1 | G86: Senegal | H86: 2026-07-01 | I86: =H86 | J86: 17:00 | K86: =IF(AND(ISNUMBER(D86),ISNUMBER(F86),ISNUMBER(Resultados!D86),ISNUMBER(Resultados!F86)),IF(SIGN(D86-F86)=SIGN(Resultados!D86-Resultados!F86),2,0)+IF(D86=Resultados!D86,1,0)+IF(F86=Resultados!F86,1,0)+IF(D86+F86=Resultados!D86+Resultados!F86,1,0),0)
A87: 83 | B87: R32 | C87: Portugal | D87: 1 | E87: X | F87: 1 | G87: Croácia | H87: 2026-07-02 | I87: =H87 | J87: 20:00 | K87: =IF(AND(ISNUMBER(D87),ISNUMBER(F87),ISNUMBER(Resultados!D87),ISNUMBER(Resultados!F87)),IF(SIGN(D87-F87)=SIGN(Resultados!D87-Resultados!F87),2,0)+IF(D87=Resultados!D87,1,0)+IF(F87=Resultados!F87,1,0)+IF(D87+F87=Resultados!D87+Resultados!F87,1,0),0)
A88: 84 | B88: R32 | C88: Espanha | D88: 2 | E88: X | F88: 0 | G88: Áustria | H88: 2026-07-02 | I88: =H88 | J88: 16:00 | K88: =IF(AND(ISNUMBER(D88),ISNUMBER(F88),ISNUMBER(Resultados!D88),ISNUMBER(Resultados!F88)),IF(SIGN(D88-F88)=SIGN(Resultados!D88-Resultados!F88),2,0)+IF(D88=Resultados!D88,1,0)+IF(F88=Resultados!F88,1,0)+IF(D88+F88=Resultados!D88+Resultados!F88,1,0),0)
A89: 85 | B89: R32 | C89: Suíça | D89: 2 | E89: X | F89: 1 | G89: Argélia | H89: 2026-07-03 | I89: =H89 | J89: 00:00 | K89: =IF(AND(ISNUMBER(D89),ISNUMBER(F89),ISNUMBER(Resultados!D89),ISNUMBER(Resultados!F89)),IF(SIGN(D89-F89)=SIGN(Resultados!D89-Resultados!F89),2,0)+IF(D89=Resultados!D89,1,0)+IF(F89=Resultados!F89,1,0)+IF(D89+F89=Resultados!D89+Resultados!F89,1,0),0)
A90: 86 | B90: R32 | C90: Argentina | D90: 3 | E90: X | F90: 0 | G90: Cabo Verde | H90: 2026-07-03 | I90: =H90 | J90: 19:00 | K90: =IF(AND(ISNUMBER(D90),ISNUMBER(F90),ISNUMBER(Resultados!D90),ISNUMBER(Resultados!F90)),IF(SIGN(D90-F90)=SIGN(Resultados!D90-Resultados!F90),2,0)+IF(D90=Resultados!D90,1,0)+IF(F90=Resultados!F90,1,0)+IF(D90+F90=Resultados!D90+Resultados!F90,1,0),0)
A91: 87 | B91: R32 | C91: Colômbia | D91: 2 | E91: X | F91: 0 | G91: Gana | H91: 2026-07-03 | I91: =H91 | J91: 22:30 | K91: =IF(AND(ISNUMBER(D91),ISNUMBER(F91),ISNUMBER(Resultados!D91),ISNUMBER(Resultados!F91)),IF(SIGN(D91-F91)=SIGN(Resultados!D91-Resultados!F91),2,0)+IF(D91=Resultados!D91,1,0)+IF(F91=Resultados!F91,1,0)+IF(D91+F91=Resultados!D91+Resultados!F91,1,0),0)
A92: 88 | B92: R32 | C92: Austrália | D92: 1 | E92: X | F92: 2 | G92: Egito | H92: 2026-07-03 | I92: =H92 | J92: 15:00 | K92: 3
A93: 89 | B93: R16 | C93: Paraguai | D93: 0 | E93: X | F93: 2 | G93: França | H93: 2026-07-04 | I93: =H93 | J93: 18:00 | K93: =IF(AND(ISNUMBER(D93),ISNUMBER(F93),ISNUMBER(Resultados!D93),ISNUMBER(Resultados!F93)),IF(SIGN(D93-F93)=SIGN(Resultados!D93-Resultados!F93),2,0)+IF(D93=Resultados!D93,1,0)+IF(F93=Resultados!F93,1,0)+IF(D93+F93=Resultados!D93+Resultados!F93,1,0),0)
A94: 90 | B94: R16 | C94: Canadá | D94: 0 | E94: X | F94: 1 | G94: Marrocos | H94: 2026-07-04 | I94: =H94 | J94: 14:00 | K94: =IF(AND(ISNUMBER(D94),ISNUMBER(F94),ISNUMBER(Resultados!D94),ISNUMBER(Resultados!F94)),IF(SIGN(D94-F94)=SIGN(Resultados!D94-Resultados!F94),2,0)+IF(D94=Resultados!D94,1,0)+IF(F94=Resultados!F94,1,0)+IF(D94+F94=Resultados!D94+Resultados!F94,1,0),0)
A95: 91 | B95: R16 | C95: Brasil | D95: 2 | E95: X | F95: 1 | G95: Noruega | H95: 2026-07-05 | I95: =H95 | J95: 17:00 | K95: =IF(AND(ISNUMBER(D95),ISNUMBER(F95),ISNUMBER(Resultados!D95),ISNUMBER(Resultados!F95)),IF(SIGN(D95-F95)=SIGN(Resultados!D95-Resultados!F95),2,0)+IF(D95=Resultados!D95,1,0)+IF(F95=Resultados!F95,1,0)+IF(D95+F95=Resultados!D95+Resultados!F95,1,0),0)
A96: 92 | B96: R16 | C96: México | D96: 1 | E96: X | F96: 1 | G96: Inglaterra | H96: 2026-07-05 | I96: =H96 | J96: 21:00 | K96: =IF(AND(ISNUMBER(D96),ISNUMBER(F96),ISNUMBER(Resultados!D96),ISNUMBER(Resultados!F96)),IF(SIGN(D96-F96)=SIGN(Resultados!D96-Resultados!F96),2,0)+IF(D96=Resultados!D96,1,0)+IF(F96=Resultados!F96,1,0)+IF(D96+F96=Resultados!D96+Resultados!F96,1,0),0)
A97: 93 | B97: R16 | C97: Portugal | D97: 1 | E97: X | F97: 2 | G97: Espanha | H97: 2026-07-06 | I97: =H97 | J97: 16:00 | K97: =IF(AND(ISNUMBER(D97),ISNUMBER(F97),ISNUMBER(Resultados!D97),ISNUMBER(Resultados!F97)),IF(SIGN(D97-F97)=SIGN(Resultados!D97-Resultados!F97),2,0)+IF(D97=Resultados!D97,1,0)+IF(F97=Resultados!F97,1,0)+IF(D97+F97=Resultados!D97+Resultados!F97,1,0),0)
A98: 94 | B98: R16 | C98: EUA | D98: 2 | E98: X | F98: 1 | G98: Bélgica | H98: 2026-07-06 | I98: =H98 | J98: 21:00 | K98: =IF(AND(ISNUMBER(D98),ISNUMBER(F98),ISNUMBER(Resultados!D98),ISNUMBER(Resultados!F98)),IF(SIGN(D98-F98)=SIGN(Resultados!D98-Resultados!F98),2,0)+IF(D98=Resultados!D98,1,0)+IF(F98=Resultados!F98,1,0)+IF(D98+F98=Resultados!D98+Resultados!F98,1,0),0)
A99: 95 | B99: R16 | C99: Argentina | D99: 2 | E99: X | F99: 0 | G99: Egito | H99: 2026-07-07 | I99: =H99 | J99: 13:00 | K99: =IF(AND(ISNUMBER(D99),ISNUMBER(F99),ISNUMBER(Resultados!D99),ISNUMBER(Resultados!F99)),IF(SIGN(D99-F99)=SIGN(Resultados!D99-Resultados!F99),2,0)+IF(D99=Resultados!D99,1,0)+IF(F99=Resultados!F99,1,0)+IF(D99+F99=Resultados!D99+Resultados!F99,1,0),0)
...

Sheet Paulo
A1: COPA 2026 - TABELA DE APOSTAS | F1: Pagamento = Pix | J1: 50 | K1: pago
A2: Nome:
A3: Celular: | D3: e-mail:
A4: JOGOS | B4: GRUPO | H4: DIA | J4: HORA
A5: 1 | B5: A | C5: México | E5: X | G5: África do Sul | H5: 46184 | I5: 46184 | J5: 0.66666667 | K5: =IF(AND(ISNUMBER(D5),ISNUMBER(F5),ISNUMBER(Resultados!D5),ISNUMBER(Resultados!F5)),IF(SIGN(D5-F5)=SIGN(Resultados!D5-Resultados!F5),2,0)+IF(D5=Resultados!D5,1,0)+IF(F5=Resultados!F5,1,0)+IF(D5+F5=Resultados!D5+Resultados!F5,1,0),0)
A6: 2 | B6: A | C6: Coreia do Sul | E6: X | G6: Tchéquia | H6: 46184 | I6: 46184 | J6: 0.95833333 | K6: =IF(AND(ISNUMBER(D6),ISNUMBER(F6),ISNUMBER(Resultados!D6),ISNUMBER(Resultados!F6)),IF(SIGN(D6-F6)=SIGN(Resultados!D6-Resultados!F6),2,0)+IF(D6=Resultados!D6,1,0)+IF(F6=Resultados!F6,1,0)+IF(D6+F6=Resultados!D6+Resultados!F6,1,0),0)
A7: 3 | B7: B | C7: Canadá | E7: X | G7: Bósnia | H7: 46185 | I7: 46185 | J7: 0.66666667 | K7: =IF(AND(ISNUMBER(D7),ISNUMBER(F7),ISNUMBER(Resultados!D7),ISNUMBER(Resultados!F7)),IF(SIGN(D7-F7)=SIGN(Resultados!D7-Resultados!F7),2,0)+IF(D7=Resultados!D7,1,0)+IF(F7=Resultados!F7,1,0)+IF(D7+F7=Resultados!D7+Resultados!F7,1,0),0)
A8: 4 | B8: D | C8: EUA | E8: X | G8: Paraguai | H8: 46185 | I8: 46185 | J8: 0.91666667 | K8: =IF(AND(ISNUMBER(D8),ISNUMBER(F8),ISNUMBER(Resultados!D8),ISNUMBER(Resultados!F8)),IF(SIGN(D8-F8)=SIGN(Resultados!D8-Resultados!F8),2,0)+IF(D8=Resultados!D8,1,0)+IF(F8=Resultados!F8,1,0)+IF(D8+F8=Resultados!D8+Resultados!F8,1,0),0)
A9: 5 | B9: D | C9: Austrália | D9: 0 | E9: X | F9: 1 | G9: Turquia | H9: 46186 | I9: 46186 | J9: 0.041666667 | K9: =IF(AND(ISNUMBER(D9),ISNUMBER(F9),ISNUMBER(Resultados!D9),ISNUMBER(Resultados!F9)),IF(SIGN(D9-F9)=SIGN(Resultados!D9-Resultados!F9),2,0)+IF(D9=Resultados!D9,1,0)+IF(F9=Resultados!F9,1,0)+IF(D9+F9=Resultados!D9+Resultados!F9,1,0),0)
A10: 6 | B10: B | C10: Catar | D10: 0 | E10: X | F10: 2 | G10: Suíça | H10: 46186 | I10: 46186 | J10: 0.66666667 | K10: =IF(AND(ISNUMBER(D10),ISNUMBER(F10),ISNUMBER(Resultados!D10),ISNUMBER(Resultados!F10)),IF(SIGN(D10-F10)=SIGN(Resultados!D10-Resultados!F10),2,0)+IF(D10=Resultados!D10,1,0)+IF(F10=Resultados!F10,1,0)+IF(D10+F10=Resultados!D10+Resultados!F10,1,0),0)
A11: 7 | B11: C | C11: Brasil | D11: 2 | E11: X | F11: 1 | G11: Marrocos | H11: 46186 | I11: 46186 | J11: 0.79166667 | K11: =IF(AND(ISNUMBER(D11),ISNUMBER(F11),ISNUMBER(Resultados!D11),ISNUMBER(Resultados!F11)),IF(SIGN(D11-F11)=SIGN(Resultados!D11-Resultados!F11),2,0)+IF(D11=Resultados!D11,1,0)+IF(F11=Resultados!F11,1,0)+IF(D11+F11=Resultados!D11+Resultados!F11,1,0),0)
A12: 8 | B12: C | C12: Haiti | D12: 0 | E12: X | F12: 3 | G12: Escócia | H12: 46186 | I12: 46186 | J12: 0.91666667 | K12: =IF(AND(ISNUMBER(D12),ISNUMBER(F12),ISNUMBER(Resultados!D12),ISNUMBER(Resultados!F12)),IF(SIGN(D12-F12)=SIGN(Resultados!D12-Resultados!F12),2,0)+IF(D12=Resultados!D12,1,0)+IF(F12=Resultados!F12,1,0)+IF(D12+F12=Resultados!D12+Resultados!F12,1,0),0)
A13: 9 | B13: E | C13: Alemanha | D13: 4 | E13: X | F13: 0 | G13: Curaçau | H13: 46187 | I13: 46187 | J13: 0.58333333 | K13: =IF(AND(ISNUMBER(D13),ISNUMBER(F13),ISNUMBER(Resultados!D13),ISNUMBER(Resultados!F13)),IF(SIGN(D13-F13)=SIGN(Resultados!D13-Resultados!F13),2,0)+IF(D13=Resultados!D13,1,0)+IF(F13=Resultados!F13,1,0)+IF(D13+F13=Resultados!D13+Resultados!F13,1,0),0)
A14: 10 | B14: F | C14: Holanda | D14: 1 | E14: X | F14: 1 | G14: Japão | H14: 46187 | I14: 46187 | J14: 0.70833333 | K14: =IF(AND(ISNUMBER(D14),ISNUMBER(F14),ISNUMBER(Resultados!D14),ISNUMBER(Resultados!F14)),IF(SIGN(D14-F14)=SIGN(Resultados!D14-Resultados!F14),2,0)+IF(D14=Resultados!D14,1,0)+IF(F14=Resultados!F14,1,0)+IF(D14+F14=Resultados!D14+Resultados!F14,1,0),0)
A15: 11 | B15: E | C15: Costa do Marfim | D15: 1 | E15: X | F15: 3 | G15: Equador | H15: 46187 | I15: 46187 | J15: 0.83333333 | K15: =IF(AND(ISNUMBER(D15),ISNUMBER(F15),ISNUMBER(Resultados!D15),ISNUMBER(Resultados!F15)),IF(SIGN(D15-F15)=SIGN(Resultados!D15-Resultados!F15),2,0)+IF(D15=Resultados!D15,1,0)+IF(F15=Resultados!F15,1,0)+IF(D15+F15=Resultados!D15+Resultados!F15,1,0),0)
A16: 12 | B16: F | C16: Suécia | D16: 2 | E16: X | F16: 0 | G16: Tunísia | H16: 46187 | I16: 46187 | J16: 0.95833333 | K16: =IF(AND(ISNUMBER(D16),ISNUMBER(F16),ISNUMBER(Resultados!D16),ISNUMBER(Resultados!F16)),IF(SIGN(D16-F16)=SIGN(Resultados!D16-Resultados!F16),2,0)+IF(D16=Resultados!D16,1,0)+IF(F16=Resultados!F16,1,0)+IF(D16+F16=Resultados!D16+Resultados!F16,1,0),0)
A17: 13 | B17: H | C17: Espanha | D17: 5 | E17: X | F17: 0 | G17: Cabo Verde | H17: 46188 | I17: 46188 | J17: 0.54166667 | K17: =IF(AND(ISNUMBER(D17),ISNUMBER(F17),ISNUMBER(Resultados!D17),ISNUMBER(Resultados!F17)),IF(SIGN(D17-F17)=SIGN(Resultados!D17-Resultados!F17),2,0)+IF(D17=Resultados!D17,1,0)+IF(F17=Resultados!F17,1,0)+IF(D17+F17=Resultados!D17+Resultados!F17,1,0),0)
A18: 14 | B18: G | C18: Bélgica | D18: 3 | E18: X | F18: 1 | G18: Egito | H18: 46188 | I18: 46188 | J18: 0.66666667 | K18: =IF(AND(ISNUMBER(D18),ISNUMBER(F18),ISNUMBER(Resultados!D18),ISNUMBER(Resultados!F18)),IF(SIGN(D18-F18)=SIGN(Resultados!D18-Resultados!F18),2,0)+IF(D18=Resultados!D18,1,0)+IF(F18=Resultados!F18,1,0)+IF(D18+F18=Resultados!D18+Resultados!F18,1,0),0)
